[2022-08-18 07:06:04,322: INFO/MainProcess] DatabaseScheduler: Schedule changed.
[2022-08-18 07:06:26,662: WARNING/MainProcess] Traceback (most recent call last):
[2022-08-18 07:06:26,662: WARNING/MainProcess]   File "/home/guest/Desktop/venv/lib/python3.8/site-packages/celery/beat.py", line 649, in start
[2022-08-18 07:06:26,663: WARNING/MainProcess]     
[2022-08-18 07:06:26,663: WARNING/MainProcess] time.sleep(interval)
[2022-08-18 07:06:26,663: WARNING/MainProcess]   File "/home/guest/Desktop/venv/lib/python3.8/site-packages/celery/apps/beat.py", line 150, in _sync
[2022-08-18 07:06:26,663: WARNING/MainProcess]     
[2022-08-18 07:06:26,663: WARNING/MainProcess] service.sync()
[2022-08-18 07:06:26,664: WARNING/MainProcess]   File "/home/guest/Desktop/venv/lib/python3.8/site-packages/celery/beat.py", line 658, in sync
[2022-08-18 07:06:26,664: WARNING/MainProcess]     
[2022-08-18 07:06:26,664: WARNING/MainProcess] self.scheduler.close()
[2022-08-18 07:06:26,664: WARNING/MainProcess]   File "/home/guest/Desktop/venv/lib/python3.8/site-packages/celery/beat.py", line 439, in close
[2022-08-18 07:06:26,664: WARNING/MainProcess]     
[2022-08-18 07:06:26,664: WARNING/MainProcess] self.sync()
[2022-08-18 07:06:26,664: WARNING/MainProcess]   File "/home/guest/Desktop/venv/lib/python3.8/site-packages/django_celery_beat/schedulers.py", line 298, in sync
[2022-08-18 07:06:26,698: WARNING/MainProcess]     
[2022-08-18 07:06:26,698: WARNING/MainProcess] self.schedule[name].save()
[2022-08-18 07:06:26,698: WARNING/MainProcess]   File "/home/guest/Desktop/venv/lib/python3.8/site-packages/django_celery_beat/schedulers.py", line 161, in save
[2022-08-18 07:06:26,698: WARNING/MainProcess]     
[2022-08-18 07:06:26,699: WARNING/MainProcess] obj.save()
[2022-08-18 07:06:26,699: WARNING/MainProcess]   File "/home/guest/Desktop/venv/lib/python3.8/site-packages/django_celery_beat/models.py", line 588, in save
[2022-08-18 07:06:26,700: WARNING/MainProcess]     
[2022-08-18 07:06:26,700: WARNING/MainProcess] super().save(*args, **kwargs)
[2022-08-18 07:06:26,700: WARNING/MainProcess]   File "/home/guest/Desktop/venv/lib/python3.8/site-packages/django/db/models/base.py", line 726, in save
[2022-08-18 07:06:26,700: WARNING/MainProcess]     
[2022-08-18 07:06:26,700: WARNING/MainProcess] self.save_base(using=using, force_insert=force_insert,
[2022-08-18 07:06:26,701: WARNING/MainProcess]   File "/home/guest/Desktop/venv/lib/python3.8/site-packages/django/db/models/base.py", line 763, in save_base
[2022-08-18 07:06:26,701: WARNING/MainProcess]     
[2022-08-18 07:06:26,701: WARNING/MainProcess] updated = self._save_table(
[2022-08-18 07:06:26,701: WARNING/MainProcess]   File "/home/guest/Desktop/venv/lib/python3.8/site-packages/django/db/models/base.py", line 845, in _save_table
[2022-08-18 07:06:26,702: WARNING/MainProcess]     
[2022-08-18 07:06:26,702: WARNING/MainProcess] updated = self._do_update(base_qs, using, pk_val, values, update_fields,
[2022-08-18 07:06:26,702: WARNING/MainProcess]   File "/home/guest/Desktop/venv/lib/python3.8/site-packages/django/db/models/base.py", line 899, in _do_update
[2022-08-18 07:06:26,702: WARNING/MainProcess]     
[2022-08-18 07:06:26,703: WARNING/MainProcess] return filtered._update(values) > 0
[2022-08-18 07:06:26,703: WARNING/MainProcess]   File "/home/guest/Desktop/venv/lib/python3.8/site-packages/django/db/models/query.py", line 802, in _update
[2022-08-18 07:06:26,713: WARNING/MainProcess]     
[2022-08-18 07:06:26,713: WARNING/MainProcess] return query.get_compiler(self.db).execute_sql(CURSOR)
[2022-08-18 07:06:26,714: WARNING/MainProcess]   File "/home/guest/Desktop/venv/lib/python3.8/site-packages/django/db/models/sql/compiler.py", line 1559, in execute_sql
[2022-08-18 07:06:26,718: WARNING/MainProcess]     
[2022-08-18 07:06:26,718: WARNING/MainProcess] cursor = super().execute_sql(result_type)
[2022-08-18 07:06:26,718: WARNING/MainProcess]   File "/home/guest/Desktop/venv/lib/python3.8/site-packages/django/db/models/sql/compiler.py", line 1162, in execute_sql
[2022-08-18 07:06:26,719: WARNING/MainProcess]     
[2022-08-18 07:06:26,719: WARNING/MainProcess] sql, params = self.as_sql()
[2022-08-18 07:06:26,719: WARNING/MainProcess]   File "/home/guest/Desktop/venv/lib/python3.8/site-packages/django/db/backends/mysql/compiler.py", line 44, in as_sql
[2022-08-18 07:06:26,732: WARNING/MainProcess]     
[2022-08-18 07:06:26,732: WARNING/MainProcess] update_query, update_params = super().as_sql()
[2022-08-18 07:06:26,732: WARNING/MainProcess]   File "/home/guest/Desktop/venv/lib/python3.8/site-packages/django/db/models/sql/compiler.py", line 1525, in as_sql
[2022-08-18 07:06:26,733: WARNING/MainProcess]     
[2022-08-18 07:06:26,733: WARNING/MainProcess] val = field.get_db_prep_save(val, connection=self.connection)
[2022-08-18 07:06:26,733: WARNING/MainProcess]   File "/home/guest/Desktop/venv/lib/python3.8/site-packages/django/db/models/fields/__init__.py", line 842, in get_db_prep_save
[2022-08-18 07:06:26,733: WARNING/MainProcess]     
[2022-08-18 07:06:26,734: WARNING/MainProcess] return self.get_db_prep_value(value, connection=connection, prepared=False)
[2022-08-18 07:06:26,734: WARNING/MainProcess]   File "/home/guest/Desktop/venv/lib/python3.8/site-packages/django/db/models/fields/__init__.py", line 1428, in get_db_prep_value
[2022-08-18 07:06:26,734: WARNING/MainProcess]     
[2022-08-18 07:06:26,734: WARNING/MainProcess] return connection.ops.adapt_datetimefield_value(value)
[2022-08-18 07:06:26,734: WARNING/MainProcess]   File "/home/guest/Desktop/venv/lib/python3.8/site-packages/django/db/backends/mysql/operations.py", line 253, in adapt_datetimefield_value
[2022-08-18 07:06:26,735: WARNING/MainProcess]     
[2022-08-18 07:06:26,735: WARNING/MainProcess] raise ValueError("MySQL backend does not support timezone-aware datetimes when USE_TZ is False.")
[2022-08-18 07:06:26,735: WARNING/MainProcess] ValueError
[2022-08-18 07:06:26,735: WARNING/MainProcess] : 
[2022-08-18 07:06:26,735: WARNING/MainProcess] MySQL backend does not support timezone-aware datetimes when USE_TZ is False.
[2022-08-18 07:06:26,735: WARNING/MainProcess] 
During handling of the above exception, another exception occurred:
[2022-08-18 07:06:26,735: WARNING/MainProcess] Traceback (most recent call last):
[2022-08-18 07:06:26,736: WARNING/MainProcess]   File "/home/guest/Desktop/venv/bin/celery", line 8, in <module>
[2022-08-18 07:06:26,736: WARNING/MainProcess]     
[2022-08-18 07:06:26,736: WARNING/MainProcess] sys.exit(main())
[2022-08-18 07:06:26,736: WARNING/MainProcess]   File "/home/guest/Desktop/venv/lib/python3.8/site-packages/celery/__main__.py", line 15, in main
[2022-08-18 07:06:26,736: WARNING/MainProcess]     
[2022-08-18 07:06:26,736: WARNING/MainProcess] sys.exit(_main())
[2022-08-18 07:06:26,736: WARNING/MainProcess]   File "/home/guest/Desktop/venv/lib/python3.8/site-packages/celery/bin/celery.py", line 217, in main
[2022-08-18 07:06:26,737: WARNING/MainProcess]     
[2022-08-18 07:06:26,737: WARNING/MainProcess] return celery(auto_envvar_prefix="CELERY")
[2022-08-18 07:06:26,737: WARNING/MainProcess]   File "/home/guest/Desktop/venv/lib/python3.8/site-packages/click/core.py", line 1130, in __call__
[2022-08-18 07:06:26,737: WARNING/MainProcess]     
[2022-08-18 07:06:26,738: WARNING/MainProcess] return self.main(*args, **kwargs)
[2022-08-18 07:06:26,738: WARNING/MainProcess]   File "/home/guest/Desktop/venv/lib/python3.8/site-packages/click/core.py", line 1055, in main
[2022-08-18 07:06:26,738: WARNING/MainProcess]     
[2022-08-18 07:06:26,738: WARNING/MainProcess] rv = self.invoke(ctx)
[2022-08-18 07:06:26,738: WARNING/MainProcess]   File "/home/guest/Desktop/venv/lib/python3.8/site-packages/click/core.py", line 1657, in invoke
[2022-08-18 07:06:26,739: WARNING/MainProcess]     
[2022-08-18 07:06:26,739: WARNING/MainProcess] return _process_result(sub_ctx.command.invoke(sub_ctx))
[2022-08-18 07:06:26,739: WARNING/MainProcess]   File "/home/guest/Desktop/venv/lib/python3.8/site-packages/click/core.py", line 1404, in invoke
[2022-08-18 07:06:26,740: WARNING/MainProcess]     
[2022-08-18 07:06:26,740: WARNING/MainProcess] return ctx.invoke(self.callback, **ctx.params)
[2022-08-18 07:06:26,740: WARNING/MainProcess]   File "/home/guest/Desktop/venv/lib/python3.8/site-packages/click/core.py", line 760, in invoke
[2022-08-18 07:06:26,740: WARNING/MainProcess]     
[2022-08-18 07:06:26,741: WARNING/MainProcess] return __callback(*args, **kwargs)
[2022-08-18 07:06:26,741: WARNING/MainProcess]   File "/home/guest/Desktop/venv/lib/python3.8/site-packages/click/decorators.py", line 26, in new_func
[2022-08-18 07:06:26,741: WARNING/MainProcess]     
[2022-08-18 07:06:26,741: WARNING/MainProcess] return f(get_current_context(), *args, **kwargs)
[2022-08-18 07:06:26,741: WARNING/MainProcess]   File "/home/guest/Desktop/venv/lib/python3.8/site-packages/celery/bin/base.py", line 134, in caller
[2022-08-18 07:06:26,741: WARNING/MainProcess]     
[2022-08-18 07:06:26,741: WARNING/MainProcess] return f(ctx, *args, **kwargs)
[2022-08-18 07:06:26,742: WARNING/MainProcess]   File "/home/guest/Desktop/venv/lib/python3.8/site-packages/celery/bin/beat.py", line 72, in beat
[2022-08-18 07:06:26,742: WARNING/MainProcess]     
[2022-08-18 07:06:26,742: WARNING/MainProcess] return beat().run()
[2022-08-18 07:06:26,742: WARNING/MainProcess]   File "/home/guest/Desktop/venv/lib/python3.8/site-packages/celery/apps/beat.py", line 77, in run
[2022-08-18 07:06:26,742: WARNING/MainProcess]     
[2022-08-18 07:06:26,742: WARNING/MainProcess] self.start_scheduler()
[2022-08-18 07:06:26,743: WARNING/MainProcess]   File "/home/guest/Desktop/venv/lib/python3.8/site-packages/celery/apps/beat.py", line 105, in start_scheduler
[2022-08-18 07:06:26,743: WARNING/MainProcess]     
[2022-08-18 07:06:26,743: WARNING/MainProcess] service.start()
[2022-08-18 07:06:26,743: WARNING/MainProcess]   File "/home/guest/Desktop/venv/lib/python3.8/site-packages/celery/beat.py", line 655, in start
[2022-08-18 07:06:26,744: WARNING/MainProcess]     
[2022-08-18 07:06:26,744: WARNING/MainProcess] self.sync()
[2022-08-18 07:06:26,744: WARNING/MainProcess]   File "/home/guest/Desktop/venv/lib/python3.8/site-packages/celery/beat.py", line 658, in sync
[2022-08-18 07:06:26,744: WARNING/MainProcess]     
[2022-08-18 07:06:26,744: WARNING/MainProcess] self.scheduler.close()
[2022-08-18 07:06:26,744: WARNING/MainProcess]   File "/home/guest/Desktop/venv/lib/python3.8/site-packages/celery/beat.py", line 439, in close
[2022-08-18 07:06:26,745: WARNING/MainProcess]     
[2022-08-18 07:06:26,745: WARNING/MainProcess] self.sync()
[2022-08-18 07:06:26,745: WARNING/MainProcess]   File "/home/guest/Desktop/venv/lib/python3.8/site-packages/django_celery_beat/schedulers.py", line 298, in sync
[2022-08-18 07:06:26,745: WARNING/MainProcess]     
[2022-08-18 07:06:26,746: WARNING/MainProcess] self.schedule[name].save()
[2022-08-18 07:06:26,746: WARNING/MainProcess]   File "/home/guest/Desktop/venv/lib/python3.8/site-packages/django_celery_beat/schedulers.py", line 161, in save
[2022-08-18 07:06:26,746: WARNING/MainProcess]     
[2022-08-18 07:06:26,746: WARNING/MainProcess] obj.save()
[2022-08-18 07:06:26,746: WARNING/MainProcess]   File "/home/guest/Desktop/venv/lib/python3.8/site-packages/django_celery_beat/models.py", line 588, in save
[2022-08-18 07:06:26,747: WARNING/MainProcess]     
[2022-08-18 07:06:26,747: WARNING/MainProcess] super().save(*args, **kwargs)
[2022-08-18 07:06:26,747: WARNING/MainProcess]   File "/home/guest/Desktop/venv/lib/python3.8/site-packages/django/db/models/base.py", line 726, in save
[2022-08-18 07:06:26,747: WARNING/MainProcess]     
[2022-08-18 07:06:26,747: WARNING/MainProcess] self.save_base(using=using, force_insert=force_insert,
[2022-08-18 07:06:26,747: WARNING/MainProcess]   File "/home/guest/Desktop/venv/lib/python3.8/site-packages/django/db/models/base.py", line 763, in save_base
[2022-08-18 07:06:26,748: WARNING/MainProcess]     
[2022-08-18 07:06:26,748: WARNING/MainProcess] updated = self._save_table(
[2022-08-18 07:06:26,748: WARNING/MainProcess]   File "/home/guest/Desktop/venv/lib/python3.8/site-packages/django/db/models/base.py", line 845, in _save_table
[2022-08-18 07:06:26,748: WARNING/MainProcess]     
[2022-08-18 07:06:26,748: WARNING/MainProcess] updated = self._do_update(base_qs, using, pk_val, values, update_fields,
[2022-08-18 07:06:26,749: WARNING/MainProcess]   File "/home/guest/Desktop/venv/lib/python3.8/site-packages/django/db/models/base.py", line 899, in _do_update
[2022-08-18 07:06:26,749: WARNING/MainProcess]     
[2022-08-18 07:06:26,749: WARNING/MainProcess] return filtered._update(values) > 0
[2022-08-18 07:06:26,749: WARNING/MainProcess]   File "/home/guest/Desktop/venv/lib/python3.8/site-packages/django/db/models/query.py", line 802, in _update
[2022-08-18 07:06:26,750: WARNING/MainProcess]     
[2022-08-18 07:06:26,750: WARNING/MainProcess] return query.get_compiler(self.db).execute_sql(CURSOR)
[2022-08-18 07:06:26,750: WARNING/MainProcess]   File "/home/guest/Desktop/venv/lib/python3.8/site-packages/django/db/models/sql/compiler.py", line 1559, in execute_sql
[2022-08-18 07:06:26,750: WARNING/MainProcess]     
[2022-08-18 07:06:26,750: WARNING/MainProcess] cursor = super().execute_sql(result_type)
[2022-08-18 07:06:26,750: WARNING/MainProcess]   File "/home/guest/Desktop/venv/lib/python3.8/site-packages/django/db/models/sql/compiler.py", line 1162, in execute_sql
[2022-08-18 07:06:26,751: WARNING/MainProcess]     
[2022-08-18 07:06:26,751: WARNING/MainProcess] sql, params = self.as_sql()
[2022-08-18 07:06:26,751: WARNING/MainProcess]   File "/home/guest/Desktop/venv/lib/python3.8/site-packages/django/db/backends/mysql/compiler.py", line 44, in as_sql
[2022-08-18 07:06:26,751: WARNING/MainProcess]     
[2022-08-18 07:06:26,751: WARNING/MainProcess] update_query, update_params = super().as_sql()
[2022-08-18 07:06:26,752: WARNING/MainProcess]   File "/home/guest/Desktop/venv/lib/python3.8/site-packages/django/db/models/sql/compiler.py", line 1525, in as_sql
[2022-08-18 07:06:26,752: WARNING/MainProcess]     
[2022-08-18 07:06:26,752: WARNING/MainProcess] val = field.get_db_prep_save(val, connection=self.connection)
[2022-08-18 07:06:26,752: WARNING/MainProcess]   File "/home/guest/Desktop/venv/lib/python3.8/site-packages/django/db/models/fields/__init__.py", line 842, in get_db_prep_save
[2022-08-18 07:06:26,753: WARNING/MainProcess]     
[2022-08-18 07:06:26,753: WARNING/MainProcess] return self.get_db_prep_value(value, connection=connection, prepared=False)
[2022-08-18 07:06:26,753: WARNING/MainProcess]   File "/home/guest/Desktop/venv/lib/python3.8/site-packages/django/db/models/fields/__init__.py", line 1428, in get_db_prep_value
[2022-08-18 07:06:26,753: WARNING/MainProcess]     
[2022-08-18 07:06:26,753: WARNING/MainProcess] return connection.ops.adapt_datetimefield_value(value)
[2022-08-18 07:06:26,754: WARNING/MainProcess]   File "/home/guest/Desktop/venv/lib/python3.8/site-packages/django/db/backends/mysql/operations.py", line 253, in adapt_datetimefield_value
[2022-08-18 07:06:26,754: WARNING/MainProcess]     
[2022-08-18 07:06:26,754: WARNING/MainProcess] raise ValueError("MySQL backend does not support timezone-aware datetimes when USE_TZ is False.")
[2022-08-18 07:06:26,754: WARNING/MainProcess] ValueError
[2022-08-18 07:06:26,754: WARNING/MainProcess] : 
[2022-08-18 07:06:26,754: WARNING/MainProcess] MySQL backend does not support timezone-aware datetimes when USE_TZ is False.
[2022-08-18 07:06:26,793: WARNING/MainProcess] Traceback (most recent call last):
[2022-08-18 07:06:26,793: WARNING/MainProcess]   File "/usr/lib/python3.8/multiprocessing/util.py", line 300, in _run_finalizers
    finalizer()
[2022-08-18 07:06:26,793: WARNING/MainProcess]   File "/usr/lib/python3.8/multiprocessing/util.py", line 224, in __call__
    res = self._callback(*self._args, **self._kwargs)
[2022-08-18 07:06:26,794: WARNING/MainProcess]   File "/home/guest/Desktop/venv/lib/python3.8/site-packages/django_celery_beat/schedulers.py", line 298, in sync
    self.schedule[name].save()
[2022-08-18 07:06:26,794: WARNING/MainProcess]   File "/home/guest/Desktop/venv/lib/python3.8/site-packages/django_celery_beat/schedulers.py", line 161, in save
    obj.save()
[2022-08-18 07:06:26,794: WARNING/MainProcess]   File "/home/guest/Desktop/venv/lib/python3.8/site-packages/django_celery_beat/models.py", line 588, in save
    super().save(*args, **kwargs)
[2022-08-18 07:06:26,794: WARNING/MainProcess]   File "/home/guest/Desktop/venv/lib/python3.8/site-packages/django/db/models/base.py", line 726, in save
    self.save_base(using=using, force_insert=force_insert,
[2022-08-18 07:06:26,794: WARNING/MainProcess]   File "/home/guest/Desktop/venv/lib/python3.8/site-packages/django/db/models/base.py", line 763, in save_base
    updated = self._save_table(
[2022-08-18 07:06:26,794: WARNING/MainProcess]   File "/home/guest/Desktop/venv/lib/python3.8/site-packages/django/db/models/base.py", line 845, in _save_table
    updated = self._do_update(base_qs, using, pk_val, values, update_fields,
[2022-08-18 07:06:26,794: WARNING/MainProcess]   File "/home/guest/Desktop/venv/lib/python3.8/site-packages/django/db/models/base.py", line 899, in _do_update
    return filtered._update(values) > 0
[2022-08-18 07:06:26,795: WARNING/MainProcess]   File "/home/guest/Desktop/venv/lib/python3.8/site-packages/django/db/models/query.py", line 802, in _update
    return query.get_compiler(self.db).execute_sql(CURSOR)
[2022-08-18 07:06:26,795: WARNING/MainProcess]   File "/home/guest/Desktop/venv/lib/python3.8/site-packages/django/db/models/sql/compiler.py", line 1559, in execute_sql
    cursor = super().execute_sql(result_type)
[2022-08-18 07:06:26,795: WARNING/MainProcess]   File "/home/guest/Desktop/venv/lib/python3.8/site-packages/django/db/models/sql/compiler.py", line 1162, in execute_sql
    sql, params = self.as_sql()
[2022-08-18 07:06:26,795: WARNING/MainProcess]   File "/home/guest/Desktop/venv/lib/python3.8/site-packages/django/db/backends/mysql/compiler.py", line 44, in as_sql
    update_query, update_params = super().as_sql()
[2022-08-18 07:06:26,795: WARNING/MainProcess]   File "/home/guest/Desktop/venv/lib/python3.8/site-packages/django/db/models/sql/compiler.py", line 1525, in as_sql
    val = field.get_db_prep_save(val, connection=self.connection)
[2022-08-18 07:06:26,795: WARNING/MainProcess]   File "/home/guest/Desktop/venv/lib/python3.8/site-packages/django/db/models/fields/__init__.py", line 842, in get_db_prep_save
    return self.get_db_prep_value(value, connection=connection, prepared=False)
[2022-08-18 07:06:26,795: WARNING/MainProcess]   File "/home/guest/Desktop/venv/lib/python3.8/site-packages/django/db/models/fields/__init__.py", line 1428, in get_db_prep_value
    return connection.ops.adapt_datetimefield_value(value)
[2022-08-18 07:06:26,795: WARNING/MainProcess]   File "/home/guest/Desktop/venv/lib/python3.8/site-packages/django/db/backends/mysql/operations.py", line 253, in adapt_datetimefield_value
    raise ValueError("MySQL backend does not support timezone-aware datetimes when USE_TZ is False.")
[2022-08-18 07:06:26,795: WARNING/MainProcess] ValueError: MySQL backend does not support timezone-aware datetimes when USE_TZ is False.
[2022-08-18 12:36:50,051: INFO/MainProcess] DatabaseScheduler: Schedule changed.
[2022-08-18 12:37:47,367: WARNING/MainProcess] Traceback (most recent call last):
[2022-08-18 12:37:47,367: WARNING/MainProcess]   File "/home/guest/Desktop/venv/lib/python3.8/site-packages/celery/beat.py", line 649, in start
[2022-08-18 12:37:47,368: WARNING/MainProcess]     
[2022-08-18 12:37:47,368: WARNING/MainProcess] time.sleep(interval)
[2022-08-18 12:37:47,368: WARNING/MainProcess]   File "/home/guest/Desktop/venv/lib/python3.8/site-packages/celery/apps/beat.py", line 150, in _sync
[2022-08-18 12:37:47,369: WARNING/MainProcess]     
[2022-08-18 12:37:47,369: WARNING/MainProcess] service.sync()
[2022-08-18 12:37:47,369: WARNING/MainProcess]   File "/home/guest/Desktop/venv/lib/python3.8/site-packages/celery/beat.py", line 658, in sync
[2022-08-18 12:37:47,369: WARNING/MainProcess]     
[2022-08-18 12:37:47,369: WARNING/MainProcess] self.scheduler.close()
[2022-08-18 12:37:47,370: WARNING/MainProcess]   File "/home/guest/Desktop/venv/lib/python3.8/site-packages/celery/beat.py", line 439, in close
[2022-08-18 12:37:47,370: WARNING/MainProcess]     
[2022-08-18 12:37:47,370: WARNING/MainProcess] self.sync()
[2022-08-18 12:37:47,370: WARNING/MainProcess]   File "/home/guest/Desktop/venv/lib/python3.8/site-packages/django_celery_beat/schedulers.py", line 298, in sync
[2022-08-18 12:37:47,370: WARNING/MainProcess]     
[2022-08-18 12:37:47,371: WARNING/MainProcess] self.schedule[name].save()
[2022-08-18 12:37:47,371: WARNING/MainProcess]   File "/home/guest/Desktop/venv/lib/python3.8/site-packages/django_celery_beat/schedulers.py", line 161, in save
[2022-08-18 12:37:47,371: WARNING/MainProcess]     
[2022-08-18 12:37:47,371: WARNING/MainProcess] obj.save()
[2022-08-18 12:37:47,371: WARNING/MainProcess]   File "/home/guest/Desktop/venv/lib/python3.8/site-packages/django_celery_beat/models.py", line 588, in save
[2022-08-18 12:37:47,371: WARNING/MainProcess]     
[2022-08-18 12:37:47,371: WARNING/MainProcess] super().save(*args, **kwargs)
[2022-08-18 12:37:47,372: WARNING/MainProcess]   File "/home/guest/Desktop/venv/lib/python3.8/site-packages/django/db/models/base.py", line 726, in save
[2022-08-18 12:37:47,372: WARNING/MainProcess]     
[2022-08-18 12:37:47,372: WARNING/MainProcess] self.save_base(using=using, force_insert=force_insert,
[2022-08-18 12:37:47,372: WARNING/MainProcess]   File "/home/guest/Desktop/venv/lib/python3.8/site-packages/django/db/models/base.py", line 763, in save_base
[2022-08-18 12:37:47,372: WARNING/MainProcess]     
[2022-08-18 12:37:47,373: WARNING/MainProcess] updated = self._save_table(
[2022-08-18 12:37:47,373: WARNING/MainProcess]   File "/home/guest/Desktop/venv/lib/python3.8/site-packages/django/db/models/base.py", line 845, in _save_table
[2022-08-18 12:37:47,373: WARNING/MainProcess]     
[2022-08-18 12:37:47,373: WARNING/MainProcess] updated = self._do_update(base_qs, using, pk_val, values, update_fields,
[2022-08-18 12:37:47,373: WARNING/MainProcess]   File "/home/guest/Desktop/venv/lib/python3.8/site-packages/django/db/models/base.py", line 899, in _do_update
[2022-08-18 12:37:47,374: WARNING/MainProcess]     
[2022-08-18 12:37:47,374: WARNING/MainProcess] return filtered._update(values) > 0
[2022-08-18 12:37:47,374: WARNING/MainProcess]   File "/home/guest/Desktop/venv/lib/python3.8/site-packages/django/db/models/query.py", line 802, in _update
[2022-08-18 12:37:47,375: WARNING/MainProcess]     
[2022-08-18 12:37:47,375: WARNING/MainProcess] return query.get_compiler(self.db).execute_sql(CURSOR)
[2022-08-18 12:37:47,375: WARNING/MainProcess]   File "/home/guest/Desktop/venv/lib/python3.8/site-packages/django/db/models/sql/compiler.py", line 1559, in execute_sql
[2022-08-18 12:37:47,375: WARNING/MainProcess]     
[2022-08-18 12:37:47,375: WARNING/MainProcess] cursor = super().execute_sql(result_type)
[2022-08-18 12:37:47,376: WARNING/MainProcess]   File "/home/guest/Desktop/venv/lib/python3.8/site-packages/django/db/models/sql/compiler.py", line 1162, in execute_sql
[2022-08-18 12:37:47,376: WARNING/MainProcess]     
[2022-08-18 12:37:47,376: WARNING/MainProcess] sql, params = self.as_sql()
[2022-08-18 12:37:47,376: WARNING/MainProcess]   File "/home/guest/Desktop/venv/lib/python3.8/site-packages/django/db/backends/mysql/compiler.py", line 44, in as_sql
[2022-08-18 12:37:47,377: WARNING/MainProcess]     
[2022-08-18 12:37:47,377: WARNING/MainProcess] update_query, update_params = super().as_sql()
[2022-08-18 12:37:47,377: WARNING/MainProcess]   File "/home/guest/Desktop/venv/lib/python3.8/site-packages/django/db/models/sql/compiler.py", line 1525, in as_sql
[2022-08-18 12:37:47,377: WARNING/MainProcess]     
[2022-08-18 12:37:47,377: WARNING/MainProcess] val = field.get_db_prep_save(val, connection=self.connection)
[2022-08-18 12:37:47,377: WARNING/MainProcess]   File "/home/guest/Desktop/venv/lib/python3.8/site-packages/django/db/models/fields/__init__.py", line 842, in get_db_prep_save
[2022-08-18 12:37:47,378: WARNING/MainProcess]     
[2022-08-18 12:37:47,378: WARNING/MainProcess] return self.get_db_prep_value(value, connection=connection, prepared=False)
[2022-08-18 12:37:47,378: WARNING/MainProcess]   File "/home/guest/Desktop/venv/lib/python3.8/site-packages/django/db/models/fields/__init__.py", line 1428, in get_db_prep_value
[2022-08-18 12:37:47,379: WARNING/MainProcess]     
[2022-08-18 12:37:47,379: WARNING/MainProcess] return connection.ops.adapt_datetimefield_value(value)
[2022-08-18 12:37:47,379: WARNING/MainProcess]   File "/home/guest/Desktop/venv/lib/python3.8/site-packages/django/db/backends/mysql/operations.py", line 253, in adapt_datetimefield_value
[2022-08-18 12:37:47,379: WARNING/MainProcess]     
[2022-08-18 12:37:47,379: WARNING/MainProcess] raise ValueError("MySQL backend does not support timezone-aware datetimes when USE_TZ is False.")
[2022-08-18 12:37:47,379: WARNING/MainProcess] ValueError
[2022-08-18 12:37:47,380: WARNING/MainProcess] : 
[2022-08-18 12:37:47,380: WARNING/MainProcess] MySQL backend does not support timezone-aware datetimes when USE_TZ is False.
[2022-08-18 12:37:47,380: WARNING/MainProcess] 
During handling of the above exception, another exception occurred:
[2022-08-18 12:37:47,380: WARNING/MainProcess] Traceback (most recent call last):
[2022-08-18 12:37:47,380: WARNING/MainProcess]   File "/home/guest/Desktop/venv/bin/celery", line 8, in <module>
[2022-08-18 12:37:47,380: WARNING/MainProcess]     
[2022-08-18 12:37:47,381: WARNING/MainProcess] sys.exit(main())
[2022-08-18 12:37:47,381: WARNING/MainProcess]   File "/home/guest/Desktop/venv/lib/python3.8/site-packages/celery/__main__.py", line 15, in main
[2022-08-18 12:37:47,381: WARNING/MainProcess]     
[2022-08-18 12:37:47,381: WARNING/MainProcess] sys.exit(_main())
[2022-08-18 12:37:47,381: WARNING/MainProcess]   File "/home/guest/Desktop/venv/lib/python3.8/site-packages/celery/bin/celery.py", line 217, in main
[2022-08-18 12:37:47,381: WARNING/MainProcess]     
[2022-08-18 12:37:47,382: WARNING/MainProcess] return celery(auto_envvar_prefix="CELERY")
[2022-08-18 12:37:47,382: WARNING/MainProcess]   File "/home/guest/Desktop/venv/lib/python3.8/site-packages/click/core.py", line 1130, in __call__
[2022-08-18 12:37:47,382: WARNING/MainProcess]     
[2022-08-18 12:37:47,382: WARNING/MainProcess] return self.main(*args, **kwargs)
[2022-08-18 12:37:47,382: WARNING/MainProcess]   File "/home/guest/Desktop/venv/lib/python3.8/site-packages/click/core.py", line 1055, in main
[2022-08-18 12:37:47,382: WARNING/MainProcess]     
[2022-08-18 12:37:47,383: WARNING/MainProcess] rv = self.invoke(ctx)
[2022-08-18 12:37:47,383: WARNING/MainProcess]   File "/home/guest/Desktop/venv/lib/python3.8/site-packages/click/core.py", line 1657, in invoke
[2022-08-18 12:37:47,383: WARNING/MainProcess]     
[2022-08-18 12:37:47,383: WARNING/MainProcess] return _process_result(sub_ctx.command.invoke(sub_ctx))
[2022-08-18 12:37:47,383: WARNING/MainProcess]   File "/home/guest/Desktop/venv/lib/python3.8/site-packages/click/core.py", line 1404, in invoke
[2022-08-18 12:37:47,384: WARNING/MainProcess]     
[2022-08-18 12:37:47,384: WARNING/MainProcess] return ctx.invoke(self.callback, **ctx.params)
[2022-08-18 12:37:47,384: WARNING/MainProcess]   File "/home/guest/Desktop/venv/lib/python3.8/site-packages/click/core.py", line 760, in invoke
[2022-08-18 12:37:47,384: WARNING/MainProcess]     
[2022-08-18 12:37:47,384: WARNING/MainProcess] return __callback(*args, **kwargs)
[2022-08-18 12:37:47,384: WARNING/MainProcess]   File "/home/guest/Desktop/venv/lib/python3.8/site-packages/click/decorators.py", line 26, in new_func
[2022-08-18 12:37:47,385: WARNING/MainProcess]     
[2022-08-18 12:37:47,385: WARNING/MainProcess] return f(get_current_context(), *args, **kwargs)
[2022-08-18 12:37:47,385: WARNING/MainProcess]   File "/home/guest/Desktop/venv/lib/python3.8/site-packages/celery/bin/base.py", line 134, in caller
[2022-08-18 12:37:47,385: WARNING/MainProcess]     
[2022-08-18 12:37:47,385: WARNING/MainProcess] return f(ctx, *args, **kwargs)
[2022-08-18 12:37:47,385: WARNING/MainProcess]   File "/home/guest/Desktop/venv/lib/python3.8/site-packages/celery/bin/beat.py", line 72, in beat
[2022-08-18 12:37:47,385: WARNING/MainProcess]     
[2022-08-18 12:37:47,385: WARNING/MainProcess] return beat().run()
[2022-08-18 12:37:47,386: WARNING/MainProcess]   File "/home/guest/Desktop/venv/lib/python3.8/site-packages/celery/apps/beat.py", line 77, in run
[2022-08-18 12:37:47,386: WARNING/MainProcess]     
[2022-08-18 12:37:47,386: WARNING/MainProcess] self.start_scheduler()
[2022-08-18 12:37:47,386: WARNING/MainProcess]   File "/home/guest/Desktop/venv/lib/python3.8/site-packages/celery/apps/beat.py", line 105, in start_scheduler
[2022-08-18 12:37:47,386: WARNING/MainProcess]     
[2022-08-18 12:37:47,386: WARNING/MainProcess] service.start()
[2022-08-18 12:37:47,386: WARNING/MainProcess]   File "/home/guest/Desktop/venv/lib/python3.8/site-packages/celery/beat.py", line 655, in start
[2022-08-18 12:37:47,387: WARNING/MainProcess]     
[2022-08-18 12:37:47,387: WARNING/MainProcess] self.sync()
[2022-08-18 12:37:47,387: WARNING/MainProcess]   File "/home/guest/Desktop/venv/lib/python3.8/site-packages/celery/beat.py", line 658, in sync
[2022-08-18 12:37:47,387: WARNING/MainProcess]     
[2022-08-18 12:37:47,387: WARNING/MainProcess] self.scheduler.close()
[2022-08-18 12:37:47,387: WARNING/MainProcess]   File "/home/guest/Desktop/venv/lib/python3.8/site-packages/celery/beat.py", line 439, in close
[2022-08-18 12:37:47,388: WARNING/MainProcess]     
[2022-08-18 12:37:47,388: WARNING/MainProcess] self.sync()
[2022-08-18 12:37:47,388: WARNING/MainProcess]   File "/home/guest/Desktop/venv/lib/python3.8/site-packages/django_celery_beat/schedulers.py", line 298, in sync
[2022-08-18 12:37:47,388: WARNING/MainProcess]     
[2022-08-18 12:37:47,388: WARNING/MainProcess] self.schedule[name].save()
[2022-08-18 12:37:47,388: WARNING/MainProcess]   File "/home/guest/Desktop/venv/lib/python3.8/site-packages/django_celery_beat/schedulers.py", line 161, in save
[2022-08-18 12:37:47,389: WARNING/MainProcess]     
[2022-08-18 12:37:47,389: WARNING/MainProcess] obj.save()
[2022-08-18 12:37:47,389: WARNING/MainProcess]   File "/home/guest/Desktop/venv/lib/python3.8/site-packages/django_celery_beat/models.py", line 588, in save
[2022-08-18 12:37:47,389: WARNING/MainProcess]     
[2022-08-18 12:37:47,389: WARNING/MainProcess] super().save(*args, **kwargs)
[2022-08-18 12:37:47,389: WARNING/MainProcess]   File "/home/guest/Desktop/venv/lib/python3.8/site-packages/django/db/models/base.py", line 726, in save
[2022-08-18 12:37:47,390: WARNING/MainProcess]     
[2022-08-18 12:37:47,390: WARNING/MainProcess] self.save_base(using=using, force_insert=force_insert,
[2022-08-18 12:37:47,390: WARNING/MainProcess]   File "/home/guest/Desktop/venv/lib/python3.8/site-packages/django/db/models/base.py", line 763, in save_base
[2022-08-18 12:37:47,390: WARNING/MainProcess]     
[2022-08-18 12:37:47,390: WARNING/MainProcess] updated = self._save_table(
[2022-08-18 12:37:47,390: WARNING/MainProcess]   File "/home/guest/Desktop/venv/lib/python3.8/site-packages/django/db/models/base.py", line 845, in _save_table
[2022-08-18 12:37:47,391: WARNING/MainProcess]     
[2022-08-18 12:37:47,391: WARNING/MainProcess] updated = self._do_update(base_qs, using, pk_val, values, update_fields,
[2022-08-18 12:37:47,391: WARNING/MainProcess]   File "/home/guest/Desktop/venv/lib/python3.8/site-packages/django/db/models/base.py", line 899, in _do_update
[2022-08-18 12:37:47,391: WARNING/MainProcess]     
[2022-08-18 12:37:47,391: WARNING/MainProcess] return filtered._update(values) > 0
[2022-08-18 12:37:47,392: WARNING/MainProcess]   File "/home/guest/Desktop/venv/lib/python3.8/site-packages/django/db/models/query.py", line 802, in _update
[2022-08-18 12:37:47,392: WARNING/MainProcess]     
[2022-08-18 12:37:47,392: WARNING/MainProcess] return query.get_compiler(self.db).execute_sql(CURSOR)
[2022-08-18 12:37:47,392: WARNING/MainProcess]   File "/home/guest/Desktop/venv/lib/python3.8/site-packages/django/db/models/sql/compiler.py", line 1559, in execute_sql
[2022-08-18 12:37:47,393: WARNING/MainProcess]     
[2022-08-18 12:37:47,393: WARNING/MainProcess] cursor = super().execute_sql(result_type)
[2022-08-18 12:37:47,393: WARNING/MainProcess]   File "/home/guest/Desktop/venv/lib/python3.8/site-packages/django/db/models/sql/compiler.py", line 1162, in execute_sql
[2022-08-18 12:37:47,393: WARNING/MainProcess]     
[2022-08-18 12:37:47,393: WARNING/MainProcess] sql, params = self.as_sql()
[2022-08-18 12:37:47,393: WARNING/MainProcess]   File "/home/guest/Desktop/venv/lib/python3.8/site-packages/django/db/backends/mysql/compiler.py", line 44, in as_sql
[2022-08-18 12:37:47,394: WARNING/MainProcess]     
[2022-08-18 12:37:47,394: WARNING/MainProcess] update_query, update_params = super().as_sql()
[2022-08-18 12:37:47,394: WARNING/MainProcess]   File "/home/guest/Desktop/venv/lib/python3.8/site-packages/django/db/models/sql/compiler.py", line 1525, in as_sql
[2022-08-18 12:37:47,394: WARNING/MainProcess]     
[2022-08-18 12:37:47,394: WARNING/MainProcess] val = field.get_db_prep_save(val, connection=self.connection)
[2022-08-18 12:37:47,395: WARNING/MainProcess]   File "/home/guest/Desktop/venv/lib/python3.8/site-packages/django/db/models/fields/__init__.py", line 842, in get_db_prep_save
[2022-08-18 12:37:47,395: WARNING/MainProcess]     
[2022-08-18 12:37:47,395: WARNING/MainProcess] return self.get_db_prep_value(value, connection=connection, prepared=False)
[2022-08-18 12:37:47,395: WARNING/MainProcess]   File "/home/guest/Desktop/venv/lib/python3.8/site-packages/django/db/models/fields/__init__.py", line 1428, in get_db_prep_value
[2022-08-18 12:37:47,396: WARNING/MainProcess]     
[2022-08-18 12:37:47,396: WARNING/MainProcess] return connection.ops.adapt_datetimefield_value(value)
[2022-08-18 12:37:47,396: WARNING/MainProcess]   File "/home/guest/Desktop/venv/lib/python3.8/site-packages/django/db/backends/mysql/operations.py", line 253, in adapt_datetimefield_value
[2022-08-18 12:37:47,396: WARNING/MainProcess]     
[2022-08-18 12:37:47,396: WARNING/MainProcess] raise ValueError("MySQL backend does not support timezone-aware datetimes when USE_TZ is False.")
[2022-08-18 12:37:47,396: WARNING/MainProcess] ValueError
[2022-08-18 12:37:47,397: WARNING/MainProcess] : 
[2022-08-18 12:37:47,397: WARNING/MainProcess] MySQL backend does not support timezone-aware datetimes when USE_TZ is False.
[2022-08-18 12:37:47,406: WARNING/MainProcess] Traceback (most recent call last):
[2022-08-18 12:37:47,407: WARNING/MainProcess]   File "/usr/lib/python3.8/multiprocessing/util.py", line 300, in _run_finalizers
    finalizer()
[2022-08-18 12:37:47,407: WARNING/MainProcess]   File "/usr/lib/python3.8/multiprocessing/util.py", line 224, in __call__
    res = self._callback(*self._args, **self._kwargs)
[2022-08-18 12:37:47,407: WARNING/MainProcess]   File "/home/guest/Desktop/venv/lib/python3.8/site-packages/django_celery_beat/schedulers.py", line 298, in sync
    self.schedule[name].save()
[2022-08-18 12:37:47,407: WARNING/MainProcess]   File "/home/guest/Desktop/venv/lib/python3.8/site-packages/django_celery_beat/schedulers.py", line 161, in save
    obj.save()
[2022-08-18 12:37:47,407: WARNING/MainProcess]   File "/home/guest/Desktop/venv/lib/python3.8/site-packages/django_celery_beat/models.py", line 588, in save
    super().save(*args, **kwargs)
[2022-08-18 12:37:47,407: WARNING/MainProcess]   File "/home/guest/Desktop/venv/lib/python3.8/site-packages/django/db/models/base.py", line 726, in save
    self.save_base(using=using, force_insert=force_insert,
[2022-08-18 12:37:47,407: WARNING/MainProcess]   File "/home/guest/Desktop/venv/lib/python3.8/site-packages/django/db/models/base.py", line 763, in save_base
    updated = self._save_table(
[2022-08-18 12:37:47,408: WARNING/MainProcess]   File "/home/guest/Desktop/venv/lib/python3.8/site-packages/django/db/models/base.py", line 845, in _save_table
    updated = self._do_update(base_qs, using, pk_val, values, update_fields,
[2022-08-18 12:37:47,408: WARNING/MainProcess]   File "/home/guest/Desktop/venv/lib/python3.8/site-packages/django/db/models/base.py", line 899, in _do_update
    return filtered._update(values) > 0
[2022-08-18 12:37:47,408: WARNING/MainProcess]   File "/home/guest/Desktop/venv/lib/python3.8/site-packages/django/db/models/query.py", line 802, in _update
    return query.get_compiler(self.db).execute_sql(CURSOR)
[2022-08-18 12:37:47,408: WARNING/MainProcess]   File "/home/guest/Desktop/venv/lib/python3.8/site-packages/django/db/models/sql/compiler.py", line 1559, in execute_sql
    cursor = super().execute_sql(result_type)
[2022-08-18 12:37:47,408: WARNING/MainProcess]   File "/home/guest/Desktop/venv/lib/python3.8/site-packages/django/db/models/sql/compiler.py", line 1162, in execute_sql
    sql, params = self.as_sql()
[2022-08-18 12:37:47,408: WARNING/MainProcess]   File "/home/guest/Desktop/venv/lib/python3.8/site-packages/django/db/backends/mysql/compiler.py", line 44, in as_sql
    update_query, update_params = super().as_sql()
[2022-08-18 12:37:47,408: WARNING/MainProcess]   File "/home/guest/Desktop/venv/lib/python3.8/site-packages/django/db/models/sql/compiler.py", line 1525, in as_sql
    val = field.get_db_prep_save(val, connection=self.connection)
[2022-08-18 12:37:47,408: WARNING/MainProcess]   File "/home/guest/Desktop/venv/lib/python3.8/site-packages/django/db/models/fields/__init__.py", line 842, in get_db_prep_save
    return self.get_db_prep_value(value, connection=connection, prepared=False)
[2022-08-18 12:37:47,409: WARNING/MainProcess]   File "/home/guest/Desktop/venv/lib/python3.8/site-packages/django/db/models/fields/__init__.py", line 1428, in get_db_prep_value
    return connection.ops.adapt_datetimefield_value(value)
[2022-08-18 12:37:47,409: WARNING/MainProcess]   File "/home/guest/Desktop/venv/lib/python3.8/site-packages/django/db/backends/mysql/operations.py", line 253, in adapt_datetimefield_value
    raise ValueError("MySQL backend does not support timezone-aware datetimes when USE_TZ is False.")
[2022-08-18 12:37:47,409: WARNING/MainProcess] ValueError: MySQL backend does not support timezone-aware datetimes when USE_TZ is False.
[2022-08-22 16:54:29,545: INFO/MainProcess] DatabaseScheduler: Schedule changed.
